<?xml version="1.0"?>
<robot name="Generic6DOF">

  <!-- Base Link -->
  <link name="base_link">
    <visual>
      <geometry>
        <cylinder radius="0.1" length="0.1"/>
      </geometry>
      <material name="gray">
        <color rgba="0.5 0.5 0.5 1"/>
      </material>
    </visual>
    <collision>
      <geometry>
        <cylinder radius="0.1" length="0.1"/>
      </geometry>
    </collision>
    <inertial>
      <mass value="5"/>
      <inertia ixx="0.1" ixy="0" ixz="0" iyy="0.1" iyz="0" izz="0.1"/>
    </inertial>
  </link>

  <!-- Link 1 -->
  <link name="link_1">
    <visual>
      <origin xyz="0 0 0.15" rpy="0 0 0"/>
      <geometry>
        <cylinder radius="0.05" length="0.3"/>
      </geometry>
      <material name="blue">
        <color rgba="0.2 0.4 0.8 1"/>
      </material>
    </visual>
    <collision>
      <origin xyz="0 0 0.15" rpy="0 0 0"/>
      <geometry>
        <cylinder radius="0.05" length="0.3"/>
      </geometry>
    </collision>
    <inertial>
      <mass value="1"/>
      <inertia ixx="0.01" ixy="0" ixz="0" iyy="0.01" iyz="0" izz="0.01"/>
    </inertial>
  </link>

  <!-- Joint 1 -->
  <joint name="joint_1" type="revolute">
    <parent link="base_link"/>
    <child link="link_1"/>
    <origin xyz="0 0 0.3" rpy="0 0 0"/>
    <axis xyz="0 0 1"/>
    <limit lower="-3.141592653589793" upper="3.141592653589793" effort="100" velocity="2.0"/>
  </joint>

  <!-- Link 2 -->
  <link name="link_2">
    <visual>
      <origin xyz="0 0 0.15" rpy="0 0 0"/>
      <geometry>
        <cylinder radius="0.05" length="0.3"/>
      </geometry>
      <material name="blue">
        <color rgba="0.2 0.4 0.8 1"/>
      </material>
    </visual>
    <collision>
      <origin xyz="0 0 0.15" rpy="0 0 0"/>
      <geometry>
        <cylinder radius="0.05" length="0.3"/>
      </geometry>
    </collision>
    <inertial>
      <mass value="1"/>
      <inertia ixx="0.01" ixy="0" ixz="0" iyy="0.01" iyz="0" izz="0.01"/>
    </inertial>
  </link>

  <!-- Joint 2 -->
  <joint name="joint_2" type="revolute">
    <parent link="link_1"/>
    <child link="link_2"/>
    <origin xyz="0 0 0.3" rpy="0 0 0"/>
    <axis xyz="0 0 1"/>
    <limit lower="-3.141592653589793" upper="3.141592653589793" effort="100" velocity="2.0"/>
  </joint>

  <!-- Link 3 -->
  <link name="link_3">
    <visual>
      <origin xyz="0 0 0.15" rpy="0 0 0"/>
      <geometry>
        <cylinder radius="0.05" length="0.3"/>
      </geometry>
      <material name="blue">
        <color rgba="0.2 0.4 0.8 1"/>
      </material>
    </visual>
    <collision>
      <origin xyz="0 0 0.15" rpy="0 0 0"/>
      <geometry>
        <cylinder radius="0.05" length="0.3"/>
      </geometry>
    </collision>
    <inertial>
      <mass value="1"/>
      <inertia ixx="0.01" ixy="0" ixz="0" iyy="0.01" iyz="0" izz="0.01"/>
    </inertial>
  </link>

  <!-- Joint 3 -->
  <joint name="joint_3" type="revolute">
    <parent link="link_2"/>
    <child link="link_3"/>
    <origin xyz="0 0 0.3" rpy="0 0 0"/>
    <axis xyz="0 0 1"/>
    <limit lower="-3.141592653589793" upper="3.141592653589793" effort="100" velocity="2.0"/>
  </joint>

  <!-- Link 4 -->
  <link name="link_4">
    <visual>
      <origin xyz="0 0 0.15" rpy="0 0 0"/>
      <geometry>
        <cylinder radius="0.05" length="0.3"/>
      </geometry>
      <material name="blue">
        <color rgba="0.2 0.4 0.8 1"/>
      </material>
    </visual>
    <collision>
      <origin xyz="0 0 0.15" rpy="0 0 0"/>
      <geometry>
        <cylinder radius="0.05" length="0.3"/>
      </geometry>
    </collision>
    <inertial>
      <mass value="1"/>
      <inertia ixx="0.01" ixy="0" ixz="0" iyy="0.01" iyz="0" izz="0.01"/>
    </inertial>
  </link>

  <!-- Joint 4 -->
  <joint name="joint_4" type="revolute">
    <parent link="link_3"/>
    <child link="link_4"/>
    <origin xyz="0 0 0.3" rpy="0 0 0"/>
    <axis xyz="0 0 1"/>
    <limit lower="-3.141592653589793" upper="3.141592653589793" effort="100" velocity="2.0"/>
  </joint>

  <!-- Link 5 -->
  <link name="link_5">
    <visual>
      <origin xyz="0 0 0.15" rpy="0 0 0"/>
      <geometry>
        <cylinder radius="0.05" length="0.3"/>
      </geometry>
      <material name="blue">
        <color rgba="0.2 0.4 0.8 1"/>
      </material>
    </visual>
    <collision>
      <origin xyz="0 0 0.15" rpy="0 0 0"/>
      <geometry>
        <cylinder radius="0.05" length="0.3"/>
      </geometry>
    </collision>
    <inertial>
      <mass value="1"/>
      <inertia ixx="0.01" ixy="0" ixz="0" iyy="0.01" iyz="0" izz="0.01"/>
    </inertial>
  </link>

  <!-- Joint 5 -->
  <joint name="joint_5" type="revolute">
    <parent link="link_4"/>
    <child link="link_5"/>
    <origin xyz="0 0 0.3" rpy="0 0 0"/>
    <axis xyz="0 0 1"/>
    <limit lower="-3.141592653589793" upper="3.141592653589793" effort="100" velocity="2.0"/>
  </joint>

  <!-- Link 6 -->
  <link name="link_6">
    <visual>
      <origin xyz="0 0 0.075" rpy="0 0 0"/>
      <geometry>
        <cylinder radius="0.05" length="0.15"/>
      </geometry>
      <material name="blue">
        <color rgba="0.2 0.4 0.8 1"/>
      </material>
    </visual>
    <collision>
      <origin xyz="0 0 0.075" rpy="0 0 0"/>
      <geometry>
        <cylinder radius="0.05" length="0.15"/>
      </geometry>
    </collision>
    <inertial>
      <mass value="1"/>
      <inertia ixx="0.01" ixy="0" ixz="0" iyy="0.01" iyz="0" izz="0.01"/>
    </inertial>
  </link>

  <!-- Joint 6 -->
  <joint name="joint_6" type="revolute">
    <parent link="link_5"/>
    <child link="link_6"/>
    <origin xyz="0 0 0.15" rpy="0 0 0"/>
    <axis xyz="0 0 1"/>
    <limit lower="-3.141592653589793" upper="3.141592653589793" effort="100" velocity="2.0"/>
  </joint>

  <!-- End Effector -->
  <link name="ee_link">
    <visual>
      <geometry>
        <box size="0.08 0.08 0.04"/>
      </geometry>
      <material name="red">
        <color rgba="0.8 0.2 0.2 1"/>
      </material>
    </visual>
  </link>

  <joint name="ee_joint" type="fixed">
    <parent link="link_6"/>
    <child link="ee_link"/>
    <origin xyz="0 0 0.15" rpy="0 0 0"/>
  </joint>

</robot>
